Workbook

Sheet 📊 By Station Dashboard
A1: 📊 WASTE COST BY STATION · Week of 3/23 – 3/29
A2: Waste amounts flow automatically from station sheets · Update Cost/Unit in the Waste Summary tab · 🔴 >30% of total 🟠 15–30% 🟢 <15%
A3: STATION BREAKDOWN
A4: Station | B4: Total Waste Units | C4: Waste Cost ($) | D4: % of Grand Total | E4: Top Wasted Item (by units) | F4: Highest $ Waste Item | I4: Station | J4: Waste Cost ($)
A5: 🍗 PFC Product | B5: =SUM('📊 Waste Summary'!E4:E16) -> 333 | C5: =SUM('📊 Waste Summary'!F4:F16) -> 302.525 | D5: =IFERROR(C5/'📊 Waste Summary'!F76,"") -> 0.1661578 | E5: =IFERROR(INDEX('📊 Waste Summary'!B4:B16,MATCH(MAX('📊 Waste Summary'!E4:E16),'📊 Waste Summary'!E4:E16,0)),"—") -> Biscuits | F5: =IFERROR(INDEX('📊 Waste Summary'!B4:B16,MATCH(MAX('📊 Waste Summary'!F4:F16),'📊 Waste Summary'!F4:F16,0)),"—") -> Breasts | I5: PFC Product | J5: =C5 -> 302.525
A6: 🍕 Pronto Product | B6: =SUM('📊 Waste Summary'!E17:E26) -> 93.5 | C6: =SUM('📊 Waste Summary'!F17:F26) -> 671.565 | D6: =IFERROR(C6/'📊 Waste Summary'!F76,"") -> 0.36884807 | E6: =IFERROR(INDEX('📊 Waste Summary'!B17:B26,MATCH(MAX('📊 Waste Summary'!E17:E26),'📊 Waste Summary'!E17:E26,0)),"—") -> Meatballs | F6: =IFERROR(INDEX('📊 Waste Summary'!B17:B26,MATCH(MAX('📊 Waste Summary'!F17:F26),'📊 Waste Summary'!F17:F26,0)),"—") -> Specialty Pizza | I6: Pronto Product | J6: =C6 -> 671.565
A7: 🥢 Little Wok | B7: =SUM('📊 Waste Summary'!E27:E52) -> 271 | C7: =SUM('📊 Waste Summary'!F27:F52) -> 542.854 | D7: =IFERROR(C7/'📊 Waste Summary'!F76,"") -> 0.29815528 | E7: =IFERROR(INDEX('📊 Waste Summary'!B27:B52,MATCH(MAX('📊 Waste Summary'!E27:E52),'📊 Waste Summary'!E27:E52,0)),"—") -> Chicken Eggroll | F7: =IFERROR(INDEX('📊 Waste Summary'!B27:B52,MATCH(MAX('📊 Waste Summary'!F27:F52),'📊 Waste Summary'!F27:F52,0)),"—") -> Orange Chicken | I7: Little Wok | J7: =C7 -> 542.854
A8: 🌮 Agave | B8: =SUM('📊 Waste Summary'!E53:E75) -> 89 | C8: =SUM('📊 Waste Summary'!F53:F75) -> 303.765 | D8: =IFERROR(C8/'📊 Waste Summary'!F76,"") -> 0.16683885 | E8: =IFERROR(INDEX('📊 Waste Summary'!B53:B75,MATCH(MAX('📊 Waste Summary'!E53:E75),'📊 Waste Summary'!E53:E75,0)),"—") -> Carne Asada | F8: =IFERROR(INDEX('📊 Waste Summary'!B53:B75,MATCH(MAX('📊 Waste Summary'!F53:F75),'📊 Waste Summary'!F53:F75,0)),"—") -> Carne Asada | I8: Agave | J8: =C8 -> 303.765
A9: TOTAL — ALL STATIONS | B9: =SUM(B5:B8) -> 786.5 | C9: ='📊 Waste Summary'!F76 -> 1820.709
A11: ITEM-LEVEL DETAIL BY STATION
A12: Station | B12: Item | C12: UOM | D12: Cost/Unit ($) | E12: Weekly Waste (units) | F12: Waste Cost ($) | G12: Status
A13: 🍗 PFC Product | B13: Legs | C13: ea. | D13: ='📊 Waste Summary'!D4 -> 0.517 | E13: ='📊 Waste Summary'!E4 -> 43 | F13: ='📊 Waste Summary'!F4 -> 22.231 | G13: =IF(E13>0,IF(E13>=10,"🔴 High",IF(E13>=5,"🟠 Moderate","🟢 Low")),"—") -> 🔴 High
A14: 🍗 PFC Product | B14: Thighs | C14: ea. | D14: ='📊 Waste Summary'!D5 -> 0.787 | E14: ='📊 Waste Summary'!E5 -> 33 | F14: ='📊 Waste Summary'!F5 -> 25.971 | G14: =IF(E14>0,IF(E14>=10,"🔴 High",IF(E14>=5,"🟠 Moderate","🟢 Low")),"—") -> 🔴 High
A15: 🍗 PFC Product | B15: Wings | C15: ea. | D15: ='📊 Waste Summary'!D6 -> 0.327 | E15: ='📊 Waste Summary'!E6 -> 44 | F15: ='📊 Waste Summary'!F6 -> 14.388 | G15: =IF(E15>0,IF(E15>=10,"🔴 High",IF(E15>=5,"🟠 Moderate","🟢 Low")),"—") -> 🔴 High
A16: 🍗 PFC Product | B16: Breasts | C16: ea. | D16: ='📊 Waste Summary'!D7 -> 3.707 | E16: ='📊 Waste Summary'!E7 -> 37 | F16: ='📊 Waste Summary'!F7 -> 137.159 | G16: =IF(E16>0,IF(E16>=10,"🔴 High",IF(E16>=5,"🟠 Moderate","🟢 Low")),"—") -> 🔴 High
A17: 🍗 PFC Product | B17: Biscuits | C17: ea. | D17: ='📊 Waste Summary'!D8 -> 0.3 | E17: ='📊 Waste Summary'!E8 -> 134 | F17: ='📊 Waste Summary'!F8 -> 40.2 | G17: =IF(E17>0,IF(E17>=10,"🔴 High",IF(E17>=5,"🟠 Moderate","🟢 Low")),"—") -> 🔴 High
A18: 🍗 PFC Product | B18: Popcorn Chicken | C18: ea. | D18: ='📊 Waste Summary'!D9 -> 2.127 | E18: ='📊 Waste Summary'!E9 -> 8 | F18: ='📊 Waste Summary'!F9 -> 17.016 | G18: =IF(E18>0,IF(E18>=10,"🔴 High",IF(E18>=5,"🟠 Moderate","🟢 Low")),"—") -> 🟠 Moderate
A19: 🍗 PFC Product | B19: Mashed Potato (cup) | C19: Lbs. | D19: ='📊 Waste Summary'!D10 -> 1.34 | E19: ='📊 Waste Summary'!E10 -> 0 | F19: ='📊 Waste Summary'!F10 -> 0 | G19: =IF(E19>0,IF(E19>=10,"🔴 High",IF(E19>=5,"🟠 Moderate","🟢 Low")),"—") -> —
A20: 🍗 PFC Product | B20: Mac & Cheese (cup) | C20: Lbs. | D20: ='📊 Waste Summary'!D11 -> 1.34 | E20: ='📊 Waste Summary'!E11 -> 0 | F20: ='📊 Waste Summary'!F11 -> 0 | G20: =IF(E20>0,IF(E20>=10,"🔴 High",IF(E20>=5,"🟠 Moderate","🟢 Low")),"—") -> —
A21: 🍗 PFC Product | B21: Mashed Potato (pan) | C21: Lbs. | D21: ='📊 Waste Summary'!D12 -> 1.34 | E21: ='📊 Waste Summary'!E12 -> 13 | F21: ='📊 Waste Summary'!F12 -> 17.42 | G21: =IF(E21>0,IF(E21>=10,"🔴 High",IF(E21>=5,"🟠 Moderate","🟢 Low")),"—") -> 🔴 High
A22: 🍗 PFC Product | B22: Mac & Cheese (pan) | C22: Lbs. | D22: ='📊 Waste Summary'!D13 -> 1.34 | E22: ='📊 Waste Summary'!E13 -> 5 | F22: ='📊 Waste Summary'!F13 -> 6.7 | G22: =IF(E22>0,IF(E22>=10,"🔴 High",IF(E22>=5,"🟠 Moderate","🟢 Low")),"—") -> 🟠 Moderate
A23: 🍗 PFC Product | B23: Coleslaw | C23: Lbs. | D23: ='📊 Waste Summary'!D14 -> 0.6 | E23: ='📊 Waste Summary'!E14 -> 0 | F23: ='📊 Waste Summary'!F14 -> 0 | G23: =IF(E23>0,IF(E23>=10,"🔴 High",IF(E23>=5,"🟠 Moderate","🟢 Low")),"—") -> —
A24: 🍗 PFC Product | B24: Green Bean / Broccoli | C24: Lbs. | D24: ='📊 Waste Summary'!D15 -> 1.34 | E24: ='📊 Waste Summary'!E15 -> 13 | F24: ='📊 Waste Summary'!F15 -> 17.42 | G24: =IF(E24>0,IF(E24>=10,"🔴 High",IF(E24>=5,"🟠 Moderate","🟢 Low")),"—") -> 🔴 High
... A84: 🌮 Agave | B84: Jalapeno | C84: Lbs. | D84: ='📊 Waste Summary'!D75 -> 0.4 | E84: ='📊 Waste Summary'!E75 -> 0 | F84: ='📊 Waste Summary'!F75 -> 0 | G84: =IF(E84>0,IF(E84>=10,"🔴 High",IF(E84>=5,"🟠 Moderate","🟢 Low")),"—") -> —

Sheet PFC Product
A1: PFC Product · Weekly Waste Log
A2: Item | B2: UOM | C2: Target Waste % | D2: Mon 3/23 | E2: Tue 3/24 | F2: Wed 3/25 | G2: Thu 3/26 | H2: Fri 2/27 | I2: Sat 2/28 | J2: Sun 3/29 | K2: Weekly Total | L2: Avg Daily Waste
A3: 🍗 Chicken
A4: Legs | B4: ea. | C4: 0.1 | D4: 3 | E4: 19 | F4: 6 | G4: 15 | K4: =SUM(D4:J4) -> 43 | L4: =IFERROR(AVERAGEIF(D4:J4,">0"),"") -> 10.75
A5: Thighs | B5: ea. | C5: 0.1 | D5: 11 | E5: 9 | F5: 6 | G5: 7 | K5: =SUM(D5:J5) -> 33 | L5: =IFERROR(AVERAGEIF(D5:J5,">0"),"") -> 8.25
A6: Wings | B6: ea. | C6: 0.1 | D6: 5 | E6: 12 | F6: 8 | G6: 19 | K6: =SUM(D6:J6) -> 44 | L6: =IFERROR(AVERAGEIF(D6:J6,">0"),"") -> 11
A7: Breasts | B7: ea. | C7: 0.1 | D7: 5 | E7: 10 | F7: 8 | G7: 14 | K7: =SUM(D7:J7) -> 37 | L7: =IFERROR(AVERAGEIF(D7:J7,">0"),"") -> 9.25
A8: Biscuits | B8: ea. | C8: 0.1 | D8: =48+21 -> 69 | E8: 38 | F8: 1 | G8: 26 | K8: =SUM(D8:J8) -> 134 | L8: =IFERROR(AVERAGEIF(D8:J8,">0"),"") -> 33.5
A9: Popcorn Chicken | B9: ea. | C9: 0.1 | D9: 2 | E9: 3.5 | G9: 2.5 | K9: =SUM(D9:J9) -> 8 | L9: =IFERROR(AVERAGEIF(D9:J9,">0"),"") -> 2.6666667
A11: 🥣 Cupped Sides
A12: Mashed Potato (cup) | B12: Lbs. | C12: 0.1 | D12: - | E12: - | F12: - | G12: - | K12: =SUM(D12:J12) -> 0 | L12: =IFERROR(AVERAGEIF(D12:J12,">0"),"")
A13: Mac & Cheese (cup) | B13: Lbs. | C13: 0.1 | D13: - | E13: - | F13: - | G13: - | K13: =SUM(D13:J13) -> 0 | L13: =IFERROR(AVERAGEIF(D13:J13,">0"),"")
A15: 🍲 Panned Sides
A16: Mashed Potato (pan) | B16: Lbs. | C16: 0.1 | D16: 6 | E16: 4 | F16: - | G16: 3 | K16: =SUM(D16:J16) -> 13 | L16: =IFERROR(AVERAGEIF(D16:J16,">0"),"") -> 4.3333333
A17: Mac & Cheese (pan) | B17: Lbs. | C17: 0.1 | D17: - | E17: 5 | F17: - | G17: - | K17: =SUM(D17:J17) -> 5 | L17: =IFERROR(AVERAGEIF(D17:J17,">0"),"") -> 5
A18: Coleslaw | B18: Lbs. | C18: 0.1 | D18: - | E18: - | F18: - | G18: - | K18: =SUM(D18:J18) -> 0 | L18: =IFERROR(AVERAGEIF(D18:J18,">0"),"")
A19: Green Bean / Broccoli | B19: Lbs. | C19: 0.1 | D19: 10 | E19: 0.5 | F19: 1 | G19: 1.5 | K19: =SUM(D19:J19) -> 13 | L19: =IFERROR(AVERAGEIF(D19:J19,">0"),"") -> 3.25
A20: Corn | B20: Lbs. | C20: 0.1 | D20: 3 | E20: - | F20: - | G20: - | K20: =SUM(D20:J20) -> 3 | L20: =IFERROR(AVERAGEIF(D20:J20,">0"),"") -> 3

Sheet Pronto Product
A1: Pronto Product · Weekly Waste Log
A2: Item | B2: UOM | C2: Target Waste % | D2: Mon 3/23 | E2: Tue 3/24 | F2: Wed 3/25 | G2: Thu 3/26 | H2: Fri 2/27 | I2: Sat 2/28 | J2: Sun 3/29 | K2: Weekly Total | L2: Avg Daily Waste
A3: 🍕 Pizza & Mains
A4: Pepperoni Pizza | B4: slice | C4: 0.1 | D4: 3 | E4: 2 | F4: 1 | G4: 5 | K4: =SUM(D4:J4) -> 11 | L4: =IFERROR(AVERAGEIF(D4:J4,">0"),"") -> 2.75
A5: MeatLover Pizza | B5: slice | C5: 0.1 | D5: 2 | E5: 1 | F5: 3 | G5: 0 | K5: =SUM(D5:J5) -> 6 | L5: =IFERROR(AVERAGEIF(D5:J5,">0"),"") -> 2
A6: Veggie Pizza | B6: slice | C6: 0.1 | D6: 3 | E6: 2 | F6: 3 | G6: 2 | K6: =SUM(D6:J6) -> 10 | L6: =IFERROR(AVERAGEIF(D6:J6,">0"),"") -> 2.5
A7: Specialty Pizza | B7: slice | C7: 0.1 | D7: 6 | E7: 3 | F7: 2 | G7: 3 | K7: =SUM(D7:J7) -> 14 | L7: =IFERROR(AVERAGEIF(D7:J7,">0"),"") -> 3.5
A8: Cheese Pizza | B8: slice | C8: 0.1 | D8: - | E8: - | F8: - | G8: 3 | K8: =SUM(D8:J8) -> 3 | L8: =IFERROR(AVERAGEIF(D8:J8,">0"),"") -> 3
A9: Garlic Bread | B9: ea. | C9: 0.1 | D9: 4 | E9: - | F9: 4 | G9: 6 | K9: =SUM(D9:J9) -> 14 | L9: =IFERROR(AVERAGEIF(D9:J9,">0"),"") -> 4.6666667
A10: Lasagna | B10: pan | C10: 0.1 | D10: 3 | E10: - | F10: 0.5 | G10: 1 | K10: =SUM(D10:J10) -> 4.5 | L10: =IFERROR(AVERAGEIF(D10:J10,">0"),"") -> 1.5
A11: Mozzarella Sticks | B11: ea. | C11: 0.1 | D11: - | E11: - | F11: - | G11: - | K11: =SUM(D11:J11) -> 0 | L11: =IFERROR(AVERAGEIF(D11:J11,">0"),"")
A12: Italian Sausage | B12: Lbs. | C12: 0.1 | D12: - | E12: - | F12: - | G12: - | K12: =SUM(D12:J12) -> 0 | L12: =IFERROR(AVERAGEIF(D12:J12,">0"),"")
A13: Meatballs | B13: ea. | C13: 0.1 | D13: 8 | E13: 10 | F13: 3 | G13: 10 | K13: =SUM(D13:J13) -> 31 | L13: =IFERROR(AVERAGEIF(D13:J13,">0"),"") -> 7.75

Sheet Little Wok
A1: Little Wok · Weekly Waste Log
A2: Item | B2: UOM | C2: Target Waste % | D2: Mon 3/23 | E2: Tue 3/24 | F2: Wed 3/25 | G2: Thu 3/26 | H2: Fri 2/27 | I2: Sat 2/28 | J2: Sun 3/29 | K2: Weekly Total | L2: Avg Daily Waste
A3: 🥢 Entrees
A4: Chow Mein | B4: LBS | C4: 0.1 | D4: 8 | E4: - | F4: 2 | G4: 3.5 | K4: =SUM(D4:J4) -> 13.5 | L4: =IFERROR(AVERAGEIF(D4:J4,">0"),"") -> 4.5
A5: Fried Rice | B5: LBS | C5: 0.1 | D5: 10 | E5: - | F5: 2.5 | G5: - | K5: =SUM(D5:J5) -> 12.5 | L5: =IFERROR(AVERAGEIF(D5:J5,">0"),"") -> 6.25
A6: Steamed Rice | B6: LBS | C6: 0.1 | D6: 2 | E6: 4 | F6: - | G6: 6.5 | K6: =SUM(D6:J6) -> 12.5 | L6: =IFERROR(AVERAGEIF(D6:J6,">0"),"") -> 4.1666667
A7: Ginger Fish | B7: LBS | C7: 0.1 | D7: 2 | E7: 1.5 | F7: - | G7: 2 | K7: =SUM(D7:J7) -> 5.5 | L7: =IFERROR(AVERAGEIF(D7:J7,">0"),"") -> 1.8333333
A8: Orange Chicken | B8: LBS | C8: 0.1 | D8: 10 | E8: 6.5 | F8: 2.5 | G8: 5 | K8: =SUM(D8:J8) -> 24 | L8: =IFERROR(AVERAGEIF(D8:J8,">0"),"") -> 6
A9: Green Bean Chicken | B9: LBS | C9: 0.1 | D9: 2 | E9: 3 | F9: 1 | G9: 2.5 | K9: =SUM(D9:J9) -> 8.5 | L9: =IFERROR(AVERAGEIF(D9:J9,">0"),"") -> 2.125
A10: Steamed Veggie | B10: LBS | C10: 0.1 | D10: 2 | E10: 3 | F10: - | G10: 1.5 | K10: =SUM(D10:J10) -> 6.5 | L10: =IFERROR(AVERAGEIF(D10:J10,">0"),"") -> 2.1666667
A11: Beef Broccoli | B11: LBS | C11: 0.1 | D11: 3 | E11: 0.5 | F11: 1.5 | G11: 2 | K11: =SUM(D11:J11) -> 7 | L11: =IFERROR(AVERAGEIF(D11:J11,">0"),"") -> 1.75
A12: Eggplant Tofu | B12: LBS | C12: 0.1 | D12: 3 | E12: 4.5 | F12: - | G12: 3 | K12: =SUM(D12:J12) -> 10.5 | L12: =IFERROR(AVERAGEIF(D12:J12,">0"),"") -> 3.5
A13: Chili Sweet Shrimp | B13: LBS | C13: 0.1 | D13: 2 | E13: 2.5 | F13: - | G13: 0 | K13: =SUM(D13:J13) -> 4.5 | L13: =IFERROR(AVERAGEIF(D13:J13,">0"),"") -> 2.25
A14: Ribs | B14: LBS | C14: 0.1 | D14: 4 | E14: 3 | F14: 1 | G14: 0.5 | K14: =SUM(D14:J14) -> 8.5 | L14: =IFERROR(AVERAGEIF(D14:J14,">0"),"") -> 2.125
A15: Teryaki Chicken | B15: LBS | C15: 0.1 | D15: 5 | E15: 2.5 | F15: - | G15: - | K15: =SUM(D15:J15) -> 7.5 | L15: =IFERROR(AVERAGEIF(D15:J15,">0"),"") -> 3.75
A16: Spicy Beef | B16: LBS | C16: 0.1 | D16: 2 | E16: 0.5 | F16: 1.5 | G16: 2 | K16: =SUM(D16:J16) -> 6 | L16: =IFERROR(AVERAGEIF(D16:J16,">0"),"") -> 1.5
A17: Kung Pao Chicken | B17: LBS | C17: 0.1 | D17: 2 | E17: 0 | F17: 1 | G17: 0 | K17: =SUM(D17:J17) -> 3 | L17: =IFERROR(AVERAGEIF(D17:J17,">0"),"") -> 1.5
A18: Wallnut Shrimp | B18: LBS | C18: 0.1 | D18: 2 | E18: 3.5 | F18: 1 | G18: 3 | K18: =SUM(D18:J18) -> 9.5 | L18: =IFERROR(AVERAGEIF(D18:J18,">0"),"") -> 2.375
A19: Beef Galbi | B19: LBS | C19: 0.1 | D19: - | E19: - | F19: - | G19: - | K19: =SUM(D19:J19) -> 0 | L19: =IFERROR(AVERAGEIF(D19:J19,">0"),"")
A20: Pork Belly | B20: LBS | C20: 0.1 | D20: - | E20: - | F20: - | G20: - | K20: =SUM(D20:J20) -> 0 | L20: =IFERROR(AVERAGEIF(D20:J20,">0"),"")
A22: 🥟 Sides
A23: Veggie Eggroll | B23: Ea. | C23: 0.1 | D23: 6 | E23: 8 | F23: 4 | G23: - | K23: =SUM(D23:J23) -> 18 | L23: =IFERROR(AVERAGEIF(D23:J23,">0"),"") -> 6
A24: Chicken Eggroll | B24: Ea. | C24: 0.1 | D24: 8 | E24: 8 | F24: - | G24: 12 | K24: =SUM(D24:J24) -> 28 | L24: =IFERROR(AVERAGEIF(D24:J24,">0"),"") -> 9.3333333
A25: Pork Eggroll | B25: Ea. | C25: 0.1 | D25: 10 | E25: 5 | F25: 6 | G25: 6 | K25: =SUM(D25:J25) -> 27 | L25: =IFERROR(AVERAGEIF(D25:J25,">0"),"") -> 6.75
A26: Cream Cheese Wontons | B26: Ea. | C26: 0.1 | D26: 12 | E26: - | F26: - | G26: 12 | K26: =SUM(D26:J26) -> 24 | L26: =IFERROR(AVERAGEIF(D26:J26,">0"),"") -> 12
A27: Plantains | B27: Ea. | C27: 0.1 | D27: - | E27: 6 | F27: 6 | G27: 10 | K27: =SUM(D27:J27) -> 22 | L27: =IFERROR(AVERAGEIF(D27:J27,">0"),"") -> 7.3333333
A28: Butterfly Shrimps | B28: Ea. | C28: 0.1 | D28: - | E28: - | F28: 4 | G28: - | K28: =SUM(D28:J28) -> 4 | L28: =IFERROR(AVERAGEIF(D28:J28,">0"),"") -> 4
A29: Poke Bowl | B29: Ea. | C29: 0.1 | D29: - | E29: - | F29: - | G29: - | K29: =SUM(D29:J29) -> 0 | L29: =IFERROR(AVERAGEIF(D29:J29,">0"),"")
A31: 🍜 Soups
A32: Wonton | B32: Lbs. | C32: 0.1 | D32: 2 | E32: - | F32: - | G32: 4.5 | K32: =SUM(D32:J32) -> 6.5 | L32: =IFERROR(AVERAGEIF(D32:J32,">0"),"") -> 3.25
A33: Egg Drop | B33: Lbs. | C33: 0.1 | D33: 2 | E33: - | F33: - | G33: 0 | K33: =SUM(D33:J33) -> 2 | L33: =IFERROR(AVERAGEIF(D33:J33,">0"),"") -> 2

Sheet Agave
A1: Agave · Weekly Waste Log
A2: Item | B2: UOM | C2: Target Waste % | D2: Mon 3/23 | E2: Tue 3/24 | F2: Wed 3/25 | G2: Thu 3/26 | H2: Fri 2/27 | I2: Sat 2/28 | J2: Sun 3/29 | K2: Weekly Total | L2: Avg Daily Waste
A3: 🌮 Proteins
A4: Carne Asada | B4: Lbs. | C4: 0.1 | D4: 10 | E4: 2.5 | F4: - | G4: 3 | K4: =SUM(D4:J4) -> 15.5 | L4: =IFERROR(AVERAGEIF(D4:J4,">0"),"") -> 5.1666667
A5: Chicken Tinga | B5: Lbs. | C5: 0.1 | D5: 3 | E5: - | F5: - | G5: 2.5 | K5: =SUM(D5:J5) -> 5.5 | L5: =IFERROR(AVERAGEIF(D5:J5,">0"),"") -> 2.75
A6: Beef Barbacoa | B6: Lbs. | C6: 0.1 | D6: 2 | E6: 1.5 | F6: - | G6: 3 | K6: =SUM(D6:J6) -> 6.5 | L6: =IFERROR(AVERAGEIF(D6:J6,">0"),"") -> 2.1666667
A7: Ground Beef | B7: Lbs. | C7: 0.1 | D7: 3 | E7: 2 | F7: 0.5 | G7: 3 | K7: =SUM(D7:J7) -> 8.5 | L7: =IFERROR(AVERAGEIF(D7:J7,">0"),"") -> 2.125
A8: Carnitas | B8: Lbs. | C8: 0.1 | D8: 2 | E8: 0.5 | F8: - | G8: 3 | K8: =SUM(D8:J8) -> 5.5 | L8: =IFERROR(AVERAGEIF(D8:J8,">0"),"") -> 1.8333333
A9: 16/20 Shrimp | B9: Lbs. | C9: 0.1 | D9: - | E9: - | F9: - | G9: - | K9: =SUM(D9:J9) -> 0 | L9: =IFERROR(AVERAGEIF(D9:J9,">0"),"")
A10: Breaded Shrimp | B10: Lbs. | C10: 0.1 | D10: - | E10: - | F10: - | G10: - | K10: =SUM(D10:J10) -> 0 | L10: =IFERROR(AVERAGEIF(D10:J10,">0"),"")
A11: Battered Fish | B11: Lbs. | C11: 0.1 | D11: - | E11: - | F11: - | G11: - | K11: =SUM(D11:J11) -> 0 | L11: =IFERROR(AVERAGEIF(D11:J11,">0"),"")
A13: 🍚 Rice & Beans
A14: Spanish Rice | B14: Lbs. | C14: 0.1 | D14: - | E14: 0.5 | F14: 1 | G14: 2.5 | K14: =SUM(D14:J14) -> 4 | L14: =IFERROR(AVERAGEIF(D14:J14,">0"),"") -> 1.3333333
A15: Cilantro Lime Rice | B15: Lbs. | C15: 0.1 | D15: - | E15: 3.5 | F15: 1 | G15: 1.5 | K15: =SUM(D15:J15) -> 6 | L15: =IFERROR(AVERAGEIF(D15:J15,">0"),"") -> 2
A16: Refried Beans | B16: Lbs. | C16: 0.1 | D16: 3 | E16: 2.5 | F16: 1 | G16: 3 | K16: =SUM(D16:J16) -> 9.5 | L16: =IFERROR(AVERAGEIF(D16:J16,">0"),"") -> 2.375
A17: Black Beans | B17: Lbs. | C17: 0.1 | D17: 4 | E17: 5 | F17: 1.5 | G17: 2.5 | K17: =SUM(D17:J17) -> 13 | L17: =IFERROR(AVERAGEIF(D17:J17,">0"),"") -> 3.25
A19: 🫙 Condiments & Extras
A20: Pico de Gallo | B20: Lbs. | C20: 0.1 | D20: - | E20: - | F20: - | G20: - | K20: =SUM(D20:J20) -> 0 | L20: =IFERROR(AVERAGEIF(D20:J20,">0"),"")
A21: Guacamole | B21: Lbs. | C21: 0.1 | D21: - | E21: - | F21: - | G21: - | K21: =SUM(D21:J21) -> 0 | L21: =IFERROR(AVERAGEIF(D21:J21,">0"),"")
A22: Sour Cream | B22: Lbs. | C22: 0.1 | D22: - | E22: - | F22: - | G22: - | K22: =SUM(D22:J22) -> 0 | L22: =IFERROR(AVERAGEIF(D22:J22,">0"),"")
A23: Enchilada Sauce | B23: Lbs. | C23: 0.1 | D23: 4 | E23: - | F23: - | G23: - | K23: =SUM(D23:J23) -> 4 | L23: =IFERROR(AVERAGEIF(D23:J23,">0"),"") -> 4
A24: Cheese Sauce | B24: Lbs. | C24: 0.1 | D24: 2 | E24: 3 | F24: - | G24: 4 | K24: =SUM(D24:J24) -> 9 | L24: =IFERROR(AVERAGEIF(D24:J24,">0"),"") -> 3
A25: Chipotle | B25: Lbs. | C25: 0.1 | D25: - | E25: - | F25: - | G25: - | K25: =SUM(D25:J25) -> 0 | L25: =IFERROR(AVERAGEIF(D25:J25,">0"),"")
A26: Mixed Veggies | B26: Lbs. | C26: 0.1 | D26: - | E26: - | F26: - | G26: - | K26: =SUM(D26:J26) -> 0 | L26: =IFERROR(AVERAGEIF(D26:J26,">0"),"")
A27: Taco Shell | B27: ea. | C27: 0.1 | D27: 2 | E27: - | F27: - | G27: - | K27: =SUM(D27:J27) -> 2 | L27: =IFERROR(AVERAGEIF(D27:J27,">0"),"") -> 2
A28: Lettuce | B28: Lbs. | C28: 0.1 | D28: - | E28: - | F28: - | G28: - | K28: =SUM(D28:J28) -> 0 | L28: =IFERROR(AVERAGEIF(D28:J28,">0"),"")
A29: Cabbage | B29: Lbs. | C29: 0.1 | D29: - | E29: - | F29: - | G29: - | K29: =SUM(D29:J29) -> 0 | L29: =IFERROR(AVERAGEIF(D29:J29,">0"),"")
A30: Jalapeno | B30: Lbs. | C30: 0.1 | D30: - | E30: - | F30: - | G30: - | K30: =SUM(D30:J30) -> 0 | L30: =IFERROR(AVERAGEIF(D30:J30,">0"),"")

Sheet Print Out
A1: PFC PRODUCT - Weekly Tracking
A2: PFC PRODUCT | B2: UOM | C2: 46104 | D2: =C2+1 -> 46105 | E2: =D2+1 -> 46106 | F2: =E2+1 -> 46107 | G2: =F2+1 -> 46108 | H2: =G2+1 -> 46109 | I2: =H2+1 -> 46110 | J2: Total
A3: Legs | B3: ea.
A4: Thighs | B4: ea.
A5: Wings | B5: ea.
A6: Breasts | B6: ea.
A7: Biscuits | B7: ea.
A8: Popcorn Chicken | B8: ea.
A9: Cupped Sides
A10: Mashed potato | B10: Lbs.
A11: Mac & Cheese | B11: Lbs.
A12: Panned Sides
A13: Mashed Potato | B13: Lbs.
A14: Mac & Cheese | B14: Lbs.
A15: Coleslaw | B15: Lbs.
A16: Green Bean / Broccoli | B16: Lbs.
A17: Corn | B17: Lbs.
A18: Closing Time
A20: PRONTO PRODUCT - Weekly Tracking
A21: Pronto PRODUCT (S)=Slice (W)=Whole | B21: UOM | C21: =C2 -> 46104 | D21: =D2 -> 46105 | E21: =E2 -> 46106 | F21: =F2 -> 46107 | G21: =G2 -> 46108 | H21: =H2 -> 46109 | I21: =I2 -> 46110 | J21: Total
A22: Pepperoni Pizza | B22: slice
A23: MeatLover Pizza | B23: slice
A24: Veggie Pizza | B24: slice
A25: Specialty Pizza | B25: Slice
A26: Cheese Pizza | B26: Slice
A27: Garlic bread | B27: ea.
A28: Lasagna | B28: pan
A29: Mozzarella Sticks | B29: ea.
A30: Italian Sausage | B30: Lbs.
A31: Meatballs | B31: ea.
A32: Closing Time
A34: LITTLE WOK - Weekly Tracking
A35: LITTLE WOK | B35: UOM | C35: =C21 -> 46104 | D35: =D21 -> 46105 | E35: =E21 -> 46106 | F35: =F21 -> 46107 | G35: =G21 -> 46108 | H35: =H21 -> 46109 | I35: =I21 -> 46110 | J35: Total
A36: Chow Mein | B36: LBS
A37: Fried Rice | B37: LBS
A38: Steamed Rice | B38: LBS
A39: Ginger Fish | B39: LBS
A40: Orange Chicken | B40: LBS
A41: Green Bean Chicken | B41: LBS
A42: Steamed Veggie | B42: LBS
...

Sheet 📊 Waste Summary
A1: 📊 FOOD WASTE SUMMARY · Week of 3/23 – 3/29
A2: Enter waste amounts directly in each station sheet · Update yellow Cost/Unit cells below · 🔴 >30% waste 🟠 15–30% 🟢 <15%
A3: Station | B3: Item | C3: UOM | D3: Cost/Unit ($) ✏ Edit me | E3: Weekly Waste (units) | F3: Waste Cost ($) | G3: Status | H3: Recipe Book Source
A4: PFC Product | B4: Legs | C4: ea. | D4: 0.517 | E4: ='PFC Product'!K4 -> 43 | F4: =IFERROR(D4*E4,0) -> 22.231 | G4: =IF(E4>0,IF(E4>=10,"🔴 High Waste",IF(E4>=5,"🟠 Moderate","🟢 Low")),"—") -> 🔴 High Waste | H4: Per piece — PFC recipe book
A5: PFC Product | B5: Thighs | C5: ea. | D5: 0.787 | E5: ='PFC Product'!K5 -> 33 | F5: =IFERROR(D5*E5,0) -> 25.971 | G5: =IF(E5>0,IF(E5>=10,"🔴 High Waste",IF(E5>=5,"🟠 Moderate","🟢 Low")),"—") -> 🔴 High Waste | H5: Per piece — PFC recipe book
A6: PFC Product | B6: Wings | C6: ea. | D6: 0.327 | E6: ='PFC Product'!K6 -> 44 | F6: =IFERROR(D6*E6,0) -> 14.388 | G6: =IF(E6>0,IF(E6>=10,"🔴 High Waste",IF(E6>=5,"🟠 Moderate","🟢 Low")),"—") -> 🔴 High Waste | H6: Per piece — PFC recipe book
A7: PFC Product | B7: Breasts | C7: ea. | D7: 3.707 | E7: ='PFC Product'!K7 -> 37 | F7: =IFERROR(D7*E7,0) -> 137.159 | G7: =IF(E7>0,IF(E7>=10,"🔴 High Waste",IF(E7>=5,"🟠 Moderate","🟢 Low")),"—") -> 🔴 High Waste | H7: Per piece — PFC recipe book
A8: PFC Product | B8: Biscuits | C8: ea. | D8: 0.3 | E8: ='PFC Product'!K8 -> 134 | F8: =IFERROR(D8*E8,0) -> 40.2 | G8: =IF(E8>0,IF(E8>=10,"🔴 High Waste",IF(E8>=5,"🟠 Moderate","🟢 Low")),"—") -> 🔴 High Waste | H8: Estimated per piece
A9: PFC Product | B9: Popcorn Chicken | C9: ea. | D9: 2.127 | E9: ='PFC Product'!K9 -> 8 | F9: =IFERROR(D9*E9,0) -> 17.016 | G9: =IF(E9>0,IF(E9>=10,"🔴 High Waste",IF(E9>=5,"🟠 Moderate","🟢 Low")),"—") -> 🟠 Moderate | H9: Per serving — PFC recipe book
A10: PFC Product | B10: Mashed Potato (cup) | C10: Lbs. | D10: 1.34 | E10: ='PFC Product'!K12 -> 0 | F10: =IFERROR(D10*E10,0) -> 0 | G10: =IF(E10>0,IF(E10>=10,"🔴 High Waste",IF(E10>=5,"🟠 Moderate","🟢 Low")),"—") -> — | H10: Per serving — PFC recipe book
A11: PFC Product | B11: Mac & Cheese (cup) | C11: Lbs. | D11: 1.34 | E11: ='PFC Product'!K13 -> 0 | F11: =IFERROR(D11*E11,0) -> 0 | G11: =IF(E11>0,IF(E11>=10,"🔴 High Waste",IF(E11>=5,"🟠 Moderate","🟢 Low")),"—") -> — | H11: Per serving — estimated
A12: PFC Product | B12: Mashed Potato (pan) | C12: Lbs. | D12: 1.34 | E12: ='PFC Product'!K16 -> 13 | F12: =IFERROR(D12*E12,0) -> 17.42 | G12: =IF(E12>0,IF(E12>=10,"🔴 High Waste",IF(E12>=5,"🟠 Moderate","🟢 Low")),"—") -> 🔴 High Waste | H12: Per lb — PFC recipe book
A13: PFC Product | B13: Mac & Cheese (pan) | C13: Lbs. | D13: 1.34 | E13: ='PFC Product'!K17 -> 5 | F13: =IFERROR(D13*E13,0) -> 6.7 | G13: =IF(E13>0,IF(E13>=10,"🔴 High Waste",IF(E13>=5,"🟠 Moderate","🟢 Low")),"—") -> 🟠 Moderate | H13: Per lb — estimated
A14: PFC Product | B14: Coleslaw | C14: Lbs. | D14: 0.6 | E14: ='PFC Product'!K18 -> 0 | F14: =IFERROR(D14*E14,0) -> 0 | G14: =IF(E14>0,IF(E14>=10,"🔴 High Waste",IF(E14>=5,"🟠 Moderate","🟢 Low")),"—") -> — | H14: Per lb — estimated
A15: PFC Product | B15: Green Bean / Broccoli | C15: Lbs. | D15: 1.34 | E15: ='PFC Product'!K19 -> 13 | F15: =IFERROR(D15*E15,0) -> 17.42 | G15: =IF(E15>0,IF(E15>=10,"🔴 High Waste",IF(E15>=5,"🟠 Moderate","🟢 Low")),"—") -> 🔴 High Waste | H15: Per lb — PFC recipe book (green beans)
A16: PFC Product | B16: Corn | C16: Lbs. | D16: 1.34 | E16: ='PFC Product'!K20 -> 3 | F16: =IFERROR(D16*E16,0) -> 4.02 | G16: =IF(E16>0,IF(E16>=10,"🔴 High Waste",IF(E16>=5,"🟠 Moderate","🟢 Low")),"—") -> 🟢 Low | H16: Per lb — PFC recipe book
A17: Pronto Product | B17: Pepperoni Pizza | C17: slice | D17: 10.75 | E17: ='Pronto Product'!K4 -> 11 | F17: =IFERROR(D17*E17,0) -> 118.25 | G17: =IF(E17>0,IF(E17>=10,"🔴 High Waste",IF(E17>=5,"🟠 Moderate","🟢 Low")),"—") -> 🔴 High Waste | H17: Per pizza — Pronto recipe book
A18: Pronto Product | B18: MeatLover Pizza | C18: slice | D18: 13.45 | E18: ='Pronto Product'!K5 -> 6 | F18: =IFERROR(D18*E18,0) -> 80.7 | G18: =IF(E18>0,IF(E18>=10,"🔴 High Waste",IF(E18>=5,"🟠 Moderate","🟢 Low")),"—") -> 🟠 Moderate | H18: Per pizza — Pronto recipe book
A19: Pronto Product | B19: Veggie Pizza | C19: slice | D19: 11.54 | E19: ='Pronto Product'!K6 -> 10 | F19: =IFERROR(D19*E19,0) -> 115.4 | G19: =IF(E19>0,IF(E19>=10,"🔴 High Waste",IF(E19>=5,"🟠 Moderate","🟢 Low")),"—") -> 🔴 High Waste | H19: Per pizza — Pronto recipe book
A20: Pronto Product | B20: Specialty Pizza | C20: slice | D20: 15.85 | E20: ='Pronto Product'!K7 -> 14 | F20: =IFERROR(D20*E20,0) -> 221.9 | G20: =IF(E20>0,IF(E20>=10,"🔴 High Waste",IF(E20>=5,"🟠 Moderate","🟢 Low")),"—") -> 🔴 High Waste | H20: Per pizza — Pronto recipe book (Supreme)
A21: Pronto Product | B21: Cheese Pizza | C21: slice | D21: 9.14 | E21: ='Pronto Product'!K8 -> 3 | F21: =IFERROR(D21*E21,0) -> 27.42 | G21: =IF(E21>0,IF(E21>=10,"🔴 High Waste",IF(E21>=5,"🟠 Moderate","🟢 Low")),"—") -> 🟢 Low | H21: Per pizza — Pronto recipe book
A22: Pronto Product | B22: Garlic Bread | C22: ea. | D22: 0.54 | E22: ='Pronto Product'!K9 -> 14 | F22: =IFERROR(D22*E22,0) -> 7.56 | G22: =IF(E22>0,IF(E22>=10,"🔴 High Waste",IF(E22>=5,"🟠 Moderate","🟢 Low")),"—") -> 🔴 High Waste | H22: Per piece — Pronto recipe book
A23: Pronto Product | B23: Lasagna | C23: pan | D23: 2.87 | E23: ='Pronto Product'!K10 -> 4.5 | F23: =IFERROR(D23*E23,0) -> 12.915 | G23: =IF(E23>0,IF(E23>=10,"🔴 High Waste",IF(E23>=5,"🟠 Moderate","🟢 Low")),"—") -> 🟢 Low | H23: Per serving — Pronto recipe book
A24: Pronto Product | B24: Mozzarella Sticks | C24: ea. | D24: 2.44 | E24: ='Pronto Product'!K11 -> 0 | F24: =IFERROR(D24*E24,0) -> 0 | G24: =IF(E24>0,IF(E24>=10,"🔴 High Waste",IF(E24>=5,"🟠 Moderate","🟢 Low")),"—") -> — | H24: Per serving — Pronto recipe book
A25: Pronto Product | B25: Italian Sausage | C25: Lbs. | D25: 2.92 | E25: ='Pronto Product'!K12 -> 0 | F25: =IFERROR(D25*E25,0) -> 0 | G25: =IF(E25>0,IF(E25>=10,"🔴 High Waste",IF(E25>=5,"🟠 Moderate","🟢 Low")),"—") -> — | H25: Per serving — Pronto recipe book
A26: Pronto Product | B26: Meatballs | C26: ea. | D26: 2.82 | E26: ='Pronto Product'!K13 -> 31 | F26: =IFERROR(D26*E26,0) -> 87.42 | G26: =IF(E26>0,IF(E26>=10,"🔴 High Waste",IF(E26>=5,"🟠 Moderate","🟢 Low")),"—") -> 🔴 High Waste | H26: Per serving — Pronto recipe book
A27: Little Wok | B27: Chow Mein | C27: LBS | D27: 1.8 | E27: ='Little Wok'!K4 -> 13.5 | F27: =IFERROR(D27*E27,0) -> 24.3 | G27: =IF(E27>0,IF(E27>=10,"🔴 High Waste",IF(E27>=5,"🟠 Moderate","🟢 Low")),"—") -> 🔴 High Waste | H27: Per batch — LW recipe book
A28: Little Wok | B28: Fried Rice | C28: LBS | D28: 4.355 | E28: ='Little Wok'!K5 -> 12.5 | F28: =IFERROR(D28*E28,0) -> 54.4375 | G28: =IF(E28>0,IF(E28>=10,"🔴 High Waste",IF(E28>=5,"🟠 Moderate","🟢 Low")),"—") -> 🔴 High Waste | H28: Per serving — LW recipe book
A29: Little Wok | B29: Steamed Rice | C29: LBS | D29: 3.9 | E29: ='Little Wok'!K6 -> 12.5 | F29: =IFERROR(D29*E29,0) -> 48.75 | G29: =IF(E29>0,IF(E29>=10,"🔴 High Waste",IF(E29>=5,"🟠 Moderate","🟢 Low")),"—") -> 🔴 High Waste | H29: Per batch — LW recipe book
A30: Little Wok | B30: Ginger Fish | C30: LBS | D30: 6.245 | E30: ='Little Wok'!K7 -> 5.5 | F30: =IFERROR(D30*E30,0) -> 34.3475 | G30: =IF(E30>0,IF(E30>=10,"🔴 High Waste",IF(E30>=5,"🟠 Moderate","🟢 Low")),"—") -> 🟠 Moderate | H30: Per serving — LW recipe book
A31: Little Wok | B31: Orange Chicken | C31: LBS | D31: 4 | E31: ='Little Wok'!K8 -> 24 | F31: =IFERROR(D31*E31,0) -> 96 | G31: =IF(E31>0,IF(E31>=10,"🔴 High Waste",IF(E31>=5,"🟠 Moderate","🟢 Low")),"—") -> 🔴 High Waste | H31: Per batch (10 srv) — LW recipe book
A32: Little Wok | B32: Green Bean Chicken | C32: LBS | D32: 1.45 | E32: ='Little Wok'!K9 -> 8.5 | F32: =IFERROR(D32*E32,0) -> 12.325 | G32: =IF(E32>0,IF(E32>=10,"🔴 High Waste",IF(E32>=5,"🟠 Moderate","🟢 Low")),"—") -> 🟠 Moderate | H32: Per batch (9 srv) — LW recipe book
A33: Little Wok | B33: Steamed Veggie | C33: LBS | D33: 0.85 | E33: ='Little Wok'!K10 -> 6.5 | F33: =IFERROR(D33*E33,0) -> 5.525 | G33: =IF(E33>0,IF(E33>=10,"🔴 High Waste",IF(E33>=5,"🟠 Moderate","🟢 Low")),"—") -> 🟠 Moderate | H33: Per batch — LW recipe book
A34: Little Wok | B34: Beef Broccoli | C34: LBS | D34: 1.03 | E34: ='Little Wok'!K11 -> 7 | F34: =IFERROR(D34*E34,0) -> 7.21 | G34: =IF(E34>0,IF(E34>=10,"🔴 High Waste",IF(E34>=5,"🟠 Moderate","🟢 Low")),"—") -> 🟠 Moderate | H34: Per batch (9 srv) — LW recipe book
A35: Little Wok | B35: Eggplant Tofu | C35: LBS | D35: 1.75 | E35: ='Little Wok'!K12 -> 10.5 | F35: =IFERROR(D35*E35,0) -> 18.375 | G35: =IF(E35>0,IF(E35>=10,"🔴 High Waste",IF(E35>=5,"🟠 Moderate","🟢 Low")),"—") -> 🔴 High Waste | H35: Per serving — LW recipe book
A36: Little Wok | B36: Chili Sweet Shrimp | C36: LBS | D36: 1.49 | E36: ='Little Wok'!K13 -> 4.5 | F36: =IFERROR(D36*E36,0) -> 6.705 | G36: =IF(E36>0,IF(E36>=10,"🔴 High Waste",IF(E36>=5,"🟠 Moderate","🟢 Low")),"—") -> 🟢 Low | H36: Per batch (9 srv) — LW recipe book
A37: Little Wok | B37: Ribs | C37: LBS | D37: 2.3 | E37: ='Little Wok'!K14 -> 8.5 | F37: =IFERROR(D37*E37,0) -> 19.55 | G37: =IF(E37>0,IF(E37>=10,"🔴 High Waste",IF(E37>=5,"🟠 Moderate","🟢 Low")),"—") -> 🟠 Moderate | H37: Per batch — LW recipe book (BBQ Pork Ribs)
A38: Little Wok | B38: Teryaki Chicken | C38: LBS | D38: 0.96 | E38: ='Little Wok'!K15 -> 7.5 | F38: =IFERROR(D38*E38,0) -> 7.2 | G38: =IF(E38>0,IF(E38>=10,"🔴 High Waste",IF(E38>=5,"🟠 Moderate","🟢 Low")),"—") -> 🟠 Moderate | H38: Per batch — LW recipe book
... A43: Little Wok | B43: Pork Belly | C43: LBS | D43: 6.65 | E43: ='Little Wok'!K20 -> 0 | F43: =IFERROR(D43*E43,0) -> 0 | G43: =IF(E43>0,IF(E43>=10,"🔴 High Waste",IF(E43>=5,"🟠 Moderate","🟢 Low")),"—") -> — | H43: Per serving — LW recipe book (Mao Pork Belly)
A44: Little Wok | B44: Veggie Eggroll | C44: Ea. | D44: 0.51 | E44: ='Little Wok'!K23 -> 18 | F44: =IFERROR(D44*E44,0) -> 9.18 | G44: =IF(E44>0,IF(E44>=10,"🔴 High Waste",IF(E44>=5,"🟠 Moderate","🟢 Low")),"—") -> 🔴 High Waste | H44: Per piece — LW recipe book (Veg spring roll)
...
